Workbook
Name L_MODE: Lists!$A$2:$A$5
Name L_DATASET: Lists!$B$2:$B$4
Name L_SCEN: Lists!$C$2:$C$5
Name L_UNITS: Lists!$D$2:$D$4
Name L_FINISH: Lists!$E$2:$E$4
Name L_YN: Lists!$F$2:$F$3
Name L_USE: Lists!$G$2:$G$6
Name L_METHOD: Lists!$H$2:$H$3
Name L_BTYPE: Lists!$I$2:$I$6
Name L_LOC: Lists!$J$2:$J$3
Name L_LAND: Lists!$K$2:$K$4
Name L_SCURVE: Lists!$L$2:$L$4
Name L_DRAW: Lists!$M$2:$M$3
Name L_RATETYPE: Lists!$N$2:$N$3
Name L_GRACE: Lists!$O$2:$O$3
Name L_REPAY: Lists!$P$2:$P$4
Name L_FREQ: Lists!$Q$2:$Q$4
Name L_REV: Lists!$R$2:$R$3
Name L_OPEXM: Lists!$S$2:$S$3
Name L_EXIT: Lists!$T$2:$T$3
Name PROJ_NAME: '10_Inputs'!$H$10
Name LOCATION: '10_Inputs'!$H$11
Name LOC_TYPE: '10_Inputs'!$H$12
Name PLOT_AREA: '10_Inputs'!$H$13
Name FAR: '10_Inputs'!$H$14
Name START_DATE: '10_Inputs'!$H$15
Name CONSTR_M: '10_Inputs'!$H$16
Name FX_USD: '10_Inputs'!$H$17
Name BLDG_TYPE: '10_Inputs'!$H$19
Name BASEMENT_YN: '10_Inputs'!$H$20
Name FINISH: '10_Inputs'!$H$21
Name HH_INCOME: '10_Inputs'!$H$22
Name AFFORD_MAX: '10_Inputs'!$H$23
Name EST_LOW: '10_Inputs'!$H$24
Name EST_HIGH: '10_Inputs'!$H$25
Name SAVINGS: '10_Inputs'!$H$26
Name FAMILY: '10_Inputs'!$H$27
Name HOME_LOAN: '10_Inputs'!$H$28
Name RENT_HOME_F: '10_Inputs'!$H$29
Name RENT_HOME_AREA: '10_Inputs'!$H$30
Name RENT_HOME_MONTHLY: '10_Inputs'!$H$31
Name FL_A1: '10_Inputs'!$H$33
Name FL_A2: '10_Inputs'!$H$34
Name FL_A3: '10_Inputs'!$H$35
Name FL_A4: '10_Inputs'!$H$36
Name FL_A5: '10_Inputs'!$H$37
Name FL_A6: '10_Inputs'!$H$38
Name FL_A7: '10_Inputs'!$H$39
Name FL_A8: '10_Inputs'!$H$40
Name FL_A9: '10_Inputs'!$H$41
Name FL_A10: '10_Inputs'!$H$42
Name FL_A11: '10_Inputs'!$H$43
Name FL_A12: '10_Inputs'!$H$44
Name FL_A13: '10_Inputs'!$H$45
Name FL_A14: '10_Inputs'!$H$46
Name FL_A15: '10_Inputs'!$H$47
Name FL_A16: '10_Inputs'!$H$48
Name FL_U1: '10_Inputs'!$H$50
Name FL_U2: '10_Inputs'!$H$51
Name FL_U3: '10_Inputs'!$H$52

Sheet 00_Start
B1: Rapha Development Profitability Model | M1: =HYPERLINK("#'00_Start'!A1","◂ Start") -> ◂ Start
B2: የራፋ የግንባታ ፕሮጀክት ትርፋማነት ሞዴል
B3: =PROJ_NAME&" | Scenario: "&SCEN_NAME&" | Mode: "&MODE_NAME -> SAMPLE B — B+G+8 mixed-use building, Addis Ababa | Scenario: Base | Mode: 3 Mixed
C5: Does my project make money? · ፕሮጀክቴ ያተርፋል?
C6: One workbook, two uses: a quick cost estimate for your own house (Mode 0) or full profitability, IFRS statements and a loan schedule for a commercial project (Modes 1–3).
C8: SET UP · ማዘጋጀት | I8: STATUS · ሁኔታ
G9: code | M9: helper labels
C10: 1. What are you building? | D10: 3 – Mixed (sell part, rent part) · ቅይጥ (ከፊል ሽያጭ፣ ከፊል ኪራይ) | G10: =IFERROR(MATCH(D10,L_MODE,0)-1,0) -> 3 | I10: Checks passed | J10: =CHK_PASS&" / "&CHK_TOTAL -> 23 / 23 | M10: =CHOOSE(PROJECT_MODE+1,"0 Personal residence","1 Build-to-Sell","2 Build-to-Rent","3 Mixed") -> 3 Mixed
C11: ምን እየገነቡ ነው? | I11: Model status | J11: =CHK_STATUS -> ALL CHECKS PASS
C12: 2. Which data? | D12: 3 – SAMPLE B: B+G+8 mixed-use · ምሳሌ ለ | G12: =IFERROR(MATCH(D12,L_DATASET,0),1) -> 3
C13: የትኛውን መረጃ? | I13: Verdict | J13: =VERDICT -> VIABLE
C14: 3. Scenario | D14: 1 – Base · መሠረታዊ | G14: =IFERROR(MATCH(D14,L_SCEN,0),1) -> 1 | I14: ውሳኔ | J14: =VERDICT_AM -> አዋጭ | M14: =CHOOSE(SCEN,"Base","Upside","Downside","Lender") -> Base
C15: ሁኔታ
C16: 4. Show statements in | D16: ETB '000 | G16: =IFERROR(MATCH(D16,L_UNITS,0),2) -> 2 | I16: Total development cost (ETB) | J16: =TDC -> 5.5066043e+08 | M16: =CHOOSE(UNIT_SEL,"ETB","ETB '000","ETB m") -> ETB '000
C17: የመግለጫ መለኪያ | I17: =IF(PROJECT_MODE=0,"Monthly loan instalment (ETB)","Equity IRR") -> Equity IRR | J17: =IF(PROJECT_MODE=0,LN_INSTAL_M,EIRR) -> 0.27572623
C18: =IF(AND(DATA_SET=2,PROJECT_MODE<>0),"Tip: Sample A is a personal house – choose mode 0.",IF(AND(DATA_SET=3,PROJECT_MODE<>3),"Tip: Sample B is a mixed-use building – choose mode 3.",IF(PROJECT_MODE=0,"Home view: open the Home Estimate page.","Commercial view: open the Dashboard."))) -> Commercial view: open the Dashboard.
C21: NAVIGATE · መሄጃ | F21: ALL SHEETS
C22: =HYPERLINK(IF(PROJECT_MODE=0,"#'02_Home'!A1","#'01_Dashboard'!A1"),IF(PROJECT_MODE=0,"▸ Home Estimate (one page) · የቤት ወጪ ግምት","▸ Dashboard · ዳሽቦርድ")) -> ▸ Dashboard · ዳሽቦርድ | F22: =HYPERLINK("#'01_Dashboard'!A1","01 Dashboard") -> 01 Dashboard | G22: =HYPERLINK("#'28_Tax'!A1","28 Tax") -> 28 Tax
C23: =HYPERLINK(IF(PROJECT_MODE=0,"#'10_Inputs'!A1","#'10_Inputs'!A1"),IF(PROJECT_MODE=0,"▸ Inputs – block 2 home card · ግብዓቶች","▸ Inputs · ግብዓቶች")) -> ▸ Inputs · ግብዓቶች | F23: =HYPERLINK("#'02_Home'!A1","02 Home") -> 02 Home | G23: =HYPERLINK("#'29_VAT'!A1","29 VAT") -> 29 VAT
C24: =HYPERLINK(IF(PROJECT_MODE=0,"#'22_Capex'!A1","#'11_Scenarios'!A1"),IF(PROJECT_MODE=0,"▸ Cost breakdown · የወጪ ዝርዝር","▸ Scenarios · ሁኔታዎች")) -> ▸ Scenarios · ሁኔታዎች | F24: =HYPERLINK("#'10_Inputs'!A1","10 Inputs") -> 10 Inputs | G24: =HYPERLINK("#'30_WorkingCap'!A1","30 WorkingCap") -> 30 WorkingCap
C25: =HYPERLINK(IF(PROJECT_MODE=0,"#'23_Construction'!A1","#'40_PL'!A1"),IF(PROJECT_MODE=0,"▸ Monthly cash needed · ወርሃዊ ወጪ","▸ Profit & loss · ትርፍና ኪሳራ")) -> ▸ Profit & loss · ትርፍና ኪሳራ | F25: =HYPERLINK("#'11_Scenarios'!A1","11 Scenarios") -> 11 Scenarios | G25: =HYPERLINK("#'40_PL'!A1","40 PL") -> 40 PL
C26: =HYPERLINK(IF(PROJECT_MODE=0,"#'27_Loan'!A1","#'41_BS'!A1"),IF(PROJECT_MODE=0,"▸ Home-loan schedule · የብድር ሰንጠረዥ","▸ Balance sheet · ሀብትና ዕዳ")) -> ▸ Balance sheet · ሀብትና ዕዳ | F26: =HYPERLINK("#'12_TaxLaw'!A1","12 TaxLaw") -> 12 TaxLaw | G26: =HYPERLINK("#'41_BS'!A1","41 BS") -> 41 BS
C27: =HYPERLINK(IF(PROJECT_MODE=0,"#'11_Scenarios'!A1","#'42_CF'!A1"),IF(PROJECT_MODE=0,"▸ Scenarios · ሁኔታዎች","▸ Cash flow · የገንዘብ ፍሰት")) -> ▸ Cash flow · የገንዘብ ፍሰት | F27: =HYPERLINK("#'20_Timeline'!A1","20 Timeline") -> 20 Timeline | G27: =HYPERLINK("#'42_CF'!A1","42 CF") -> 42 CF
C28: =HYPERLINK(IF(PROJECT_MODE=0,"#'60_Checks'!A1","#'27_Loan'!A1"),IF(PROJECT_MODE=0,"▸ Checks · ማረጋገጫዎች","▸ Loan schedule · የብድር ሰንጠረዥ")) -> ▸ Loan schedule · የብድር ሰንጠረዥ | F28: =HYPERLINK("#'21_Area'!A1","21 Area") -> 21 Area | G28: =HYPERLINK("#'43_Ratios'!A1","43 Ratios") -> 43 Ratios
C29: =HYPERLINK(IF(PROJECT_MODE=0,"#'61_Glossary'!A1","#'50_Returns'!A1"),IF(PROJECT_MODE=0,"▸ Glossary · መዝገበ ቃላት","▸ Returns · ተመላሽ")) -> ▸ Returns · ተመላሽ | F29: =HYPERLINK("#'22_Capex'!A1","22 Capex") -> 22 Capex | G29: =HYPERLINK("#'50_Returns'!A1","50 Returns") -> 50 Returns
C30: =HYPERLINK(IF(PROJECT_MODE=0,"#'00_Start'!A1","#'52_Sensitivity'!A1"),IF(PROJECT_MODE=0,"","▸ Sensitivity & break-even · የስጋት ትንተና")) -> ▸ Sensitivity & break-even · የስጋት ትንተና | F30: =HYPERLINK("#'23_Construction'!A1","23 Construction") -> 23 Construction | G30: =HYPERLINK("#'51_Payback'!A1","51 Payback") -> 51 Payback
C31: =HYPERLINK(IF(PROJECT_MODE=0,"#'00_Start'!A1","#'60_Checks'!A1"),IF(PROJECT_MODE=0,"","▸ Checks · ማረጋገጫዎች")) -> ▸ Checks · ማረጋገጫዎች | F31: =HYPERLINK("#'24_Revenue'!A1","24 Revenue") -> 24 Revenue | G31: =HYPERLINK("#'52_Sensitivity'!A1","52 Sensitivity") -> 52 Sensitivity
F32: =HYPERLINK("#'25_Opex'!A1","25 Opex") -> 25 Opex | G32: =HYPERLINK("#'60_Checks'!A1","60 Checks") -> 60 Checks
F33: =HYPERLINK("#'26_Assets'!A1","26 Assets") -> 26 Assets | G33: =HYPERLINK("#'61_Glossary'!A1","61 Glossary") -> 61 Glossary
F34: =HYPERLINK("#'27_Loan'!A1","27 Loan") -> 27 Loan
C37: HOW TO USE · አጠቃቀም
B38: 1 | C38: Answer question 1. Personal house → 0. Selling, renting or both → 1, 2 or 3.
C39: ጥያቄ 1ን ይመልሱ፡ የግል ቤት → 0፤ ለሽያጭ፣ ለኪራይ ወይም ለሁለቱም → 1፣ 2 ወይም 3።
B40: 2 | C40: Choose 'My project' in question 2 and type your values in column E of sheet 10 Inputs (blue cells only).
C41: በጥያቄ 2 'የእኔ ፕሮጀክት'ን ይምረጡና በገጽ 10 ዓምድ E ሰማያዊ ሕዋሶች ላይ ብቻ ይጻፉ።
B42: 3 | C42: Check the status box: all checks must pass. Then read the Home Estimate (Mode 0) or the Dashboard.
C43: የማረጋገጫ ሳጥኑን ይመልከቱ፤ ከዚያ የቤት ግምቱን ወይም ዳሽቦርዱን ያንብቡ።
B44: 4 | C44: Stress-test: switch scenarios (question 3) and use the flex cells on sheet 52.
C45: ሁኔታዎችን ይቀያይሩና በገጽ 52 የማስተካከያ ሕዋሶችን ይጠቀሙ።
C47: COLOUR CODE · የቀለም ኮድ
...

Sheet 01_Dashboard
B1: Dashboard | S1: =HYPERLINK("#'00_Start'!A1","◂ Start") -> ◂ Start
B2: ዳሽቦርድ – ፕሮጀክቴ ያተርፋል?
B3: =PROJ_NAME&" | Scenario: "&SCEN_NAME&" | Mode: "&MODE_NAME -> SAMPLE B — B+G+8 mixed-use building, Addis Ababa | Scenario: Base | Mode: 3 Mixed
B5: Scenario | C5: =SCEN_NAME -> Base | E5: Checks | F5: =CHK_PASS&" / "&CHK_TOTAL&" pass" -> 23 / 23 pass | H5: Mode | I5: =MODE_NAME -> 3 Mixed | K5: Verdict · ውሳኔ | L5: =VERDICT&" · "&VERDICT_AM -> VIABLE · አዋጭ | Q5: Equity IRR hurdle | R5: =HURDLE -> 0.2
B6: =IF(PROJECT_MODE=0,"Home view – tiles show the cost estimate; open the Home Estimate page for the full picture.","Commercial view – ETB; IRR on dated cash flows (XIRR); verdict = equity IRR vs hurdle, profit on cost and DSCR covenant.") -> Commercial view – ETB; IRR on dated cash flows (XIRR); verdict = equity IRR vs hurdle, profit on cost and DSCR covenant.
B8: =IF(PROJECT_MODE=0,"TOTAL PROJECT COST","TOTAL DEVELOPMENT COST") -> TOTAL DEVELOPMENT COST | E8: =IF(PROJECT_MODE=0,"COST PER m²","GROSS DEVELOPMENT VALUE") -> GROSS DEVELOPMENT VALUE | H8: =IF(PROJECT_MODE=0,"MONTHLY INSTALMENT","PROFIT ON COST") -> PROFIT ON COST | K8: =IF(PROJECT_MODE=0,"FUNDING GAP","EQUITY IRR") -> EQUITY IRR | N8: =IF(PROJECT_MODE=0,"LOAN DRAWN","PEAK DEBT") -> PEAK DEBT | Q8: =IF(PROJECT_MODE=0,"AFFORDABILITY","MIN DSCR") -> MIN DSCR
B10: =TDC -> 5.5066043e+08 | E10: =IF(PROJECT_MODE=0,TEXT(CC_M2,"#,##0"),GDV) -> 8.3681139e+08 | H10: =IF(PROJECT_MODE=0,TEXT(LN_INSTAL_M,"#,##0"),POC) -> 0.51965049 | K10: =IF(PROJECT_MODE=0,TEXT(FUND_GAP,"#,##0"),EIRR) -> 0.27572623 | N10: =IF(PROJECT_MODE=0,DEBT_DRAWN,PEAK_DEBT) -> 1.3314989e+08 | Q10: =IF(PROJECT_MODE=0,TEXT(AFFORD_PCT,"0%"),MIN_DSCR) -> 1.7426163
B12: ="ETB · "&TEXT(TDC_M2G,"#,##0")&" per m² gross" -> ETB · 86,041 per m² gross | E12: =IF(PROJECT_MODE=0,"construction cost per m²","GDV ÷ TDC = "&TEXT(GDV_TDC,"0.00")&"x") -> GDV ÷ TDC = 1.52x | H12: =IF(PROJECT_MODE=0,"home loan","margin on GDV "&TEXT(DEV_MARGIN,"0.0%")) -> margin on GDV 34.2% | K12: =IF(PROJECT_MODE=0,IF(FUND_GAP>0.5,"to be found","fully funded"),"hurdle "&TEXT(HURDLE,"0.0%")&IF(EIRR>=HURDLE," ✓ above"," ✗ below")) -> hurdle 20.0% ✓ above | N12: ="incl. capitalised IDC "&TEXT(IDC_TOT/1000000,"#,##0.0")&" m" -> incl. capitalised IDC 17.5 m | Q12: =IF(PROJECT_MODE=0,AFFORD_TXT,"covenant "&TEXT(DSCR_COV,"0.00")&"x"&IF(DSCR_OK=1," ✓ met"," ✗ breached")) -> covenant 1.30x ✓ met
B14: (a) Project cash flow and cumulative · ETB m | H14: (b) Loan balance at period end · ETB m | N14: (b) DSCR by year vs covenant · x (capped at 10)
B28: (c) Revenue mix · ETB m | H28: (d) Development cost breakdown · ETB m | N28: Tornado – Equity IRR swing (±20%, delay +6 mo)
B42: SOURCES & USES – construction period (ETB) | K42: ALERTS · ማስጠንቀቂያዎች
B43: Uses | E43: Sources | K43: =IF(CHK_FAIL>0,"✗ "&CHK_FAIL&" model check(s) failing – see sheet 60","✓ All model checks pass") -> ✓ All model checks pass
B44: TDC | C44: =TDC -> 5.5066043e+08 | E44: Equity committed | F44: =EQ_DRAWN -> 1.7687849e+08 | K44: =IF(PROJECT_MODE=0,"–",IF(N_BREACH>0,"✗ DSCR below covenant in "&N_BREACH&" year(s)","✓ DSCR covenant met")) -> ✓ DSCR covenant met
B45: Capex VAT (refundable) | C45: =SUM('23_Construction'!$E$36:$AZ$36) -> 39251694 | E45: Top-up / gap | F45: =FUND_GAP -> 0 | K45: =IF(FUND_GAP>0.5,"✗ Funding gap of "&TEXT(FUND_GAP,"#,##0")&" ETB","✓ Funding fully covered") -> ✓ Funding fully covered
B46: Lease paid in build | C46: =SUM('23_Construction'!$E$37:$AZ$38) -> 27585000 | E46: Bank debt drawn | F46: =DEBT_DRAWN -> 1.1561421e+08 | K46: =IF(PROJECT_MODE=0,"–",IF(N_LOWCASH>0,"! Cash below minimum in "&N_LOWCASH&" year(s)","✓ Cash above minimum")) -> ✓ Cash above minimum
E47: Presale cash used | F47: =PS_USED -> 1.5650262e+08 | K47: =IF(PROJECT_MODE=0,"–",IF(N_IMPAIR>0,"! IAS 36 impairment indicator in "&N_IMPAIR&" year(s)","✓ No impairment indicator")) -> ✓ No impairment indicator
E48: IDC capitalised | F48: =IDC_TOT -> 17535682 | K48: =IF(AND(FAR>0,FAR_ACT>FAR),"! FAR "&TEXT(FAR_ACT,"0.00")&" exceeds permitted "&TEXT(FAR,"0.00"),"✓ FAR within limit") -> ✓ FAR within limit
E49: Land non-cash | F49: =LAND_TOT-LANDCASH_TOT -> 135000000 | K49: =IF(PROJECT_MODE=0,"–",IF(EIRR<HURDLE,"! Equity IRR below hurdle","✓ Equity IRR above hurdle")) -> ✓ Equity IRR above hurdle
E50: Retention held | F50: =RET_TOT -> 15966117 | K50: ="! Tax rates must be verified (sheet 12) · የግብር መጣኔዎችን ያረጋግጡ" -> ! Tax rates must be verified (sheet 12) · የግብር መጣኔዎችን ያረጋግጡ
B51: Total uses | C51: =SUM(C44:C50) -> 6.1749713e+08 | E51: Total sources | F51: =SUM(F44:F50) -> 6.1749713e+08
E52: Check (= 0) | F52: =ROUND(F51-C51,0) -> 0
B62: Chart data (linked – do not edit)
B63: Period | C63: ='20_Timeline'!E12 -> C1 | D63: ='20_Timeline'!F12 -> C2 | E63: ='20_Timeline'!G12 -> C3 | F63: ='20_Timeline'!H12 -> C4 | G63: ='20_Timeline'!I12 -> O1 | H63: ='20_Timeline'!J12 -> O2 | I63: ='20_Timeline'!K12 -> O3 | J63: ='20_Timeline'!L12 -> O4 | ... P63: ='20_Timeline'!R12 -> O10
B64: Project cash flow | C64: ='50_Returns'!E22/1000000 -> -89.631042 | D64: ='50_Returns'!F22/1000000 -> -144.81592 | E64: ='50_Returns'!G22/1000000 -> 145.97377 | F64: ='50_Returns'!H22/1000000 -> -0.20127724 | G64: ='50_Returns'!I22/1000000 -> 90.458332 | H64: ='50_Returns'!J22/1000000 -> 77.263208 | I64: ='50_Returns'!K22/1000000 -> 8.4457986 | J64: ='50_Returns'!L22/1000000 -> 14.240871 | ... P64: ='50_Returns'!R22/1000000 -> 640.00115
B65: Cumulative | C65: ='51_Payback'!E12/1000000 -> -89.631042 | D65: ='51_Payback'!F12/1000000 -> -234.44696 | E65: ='51_Payback'!G12/1000000 -> -88.47319 | F65: ='51_Payback'!H12/1000000 -> -88.674467 | G65: ='51_Payback'!I12/1000000 -> 1.7838649 | H65: ='51_Payback'!J12/1000000 -> 79.047073 | I65: ='51_Payback'!K12/1000000 -> 87.492872 | J65: ='51_Payback'!L12/1000000 -> 101.73374 | ... P65: ='51_Payback'!R12/1000000 -> 841.70561
B66: Loan balance | C66: ='27_Loan'!E20/1000000 -> 0 | D66: ='27_Loan'!F20/1000000 -> 111.77085 | E66: ='27_Loan'!G20/1000000 -> 133.14989 | F66: ='27_Loan'!H20/1000000 -> 133.14989 | G66: ='27_Loan'!I20/1000000 -> 54.4129 | H66: ='27_Loan'!J20/1000000 -> 22.362969 | I66: ='27_Loan'!K20/1000000 -> 20.784742 | J66: ='27_Loan'!L20/1000000 -> 18.956128 | ... P66: ='27_Loan'!R20/1000000 -> 0
B67: DSCR | C67: =IF(ISNUMBER('43_Ratios'!E12),MIN(10,'43_Ratios'!E12),0) -> 0 | D67: =IF(ISNUMBER('43_Ratios'!F12),MIN(10,'43_Ratios'!F12),0) -> 0 | E67: =IF(ISNUMBER('43_Ratios'!G12),MIN(10,'43_Ratios'!G12),0) -> 0 | F67: =IF(ISNUMBER('43_Ratios'!H12),MIN(10,'43_Ratios'!H12),0) -> 0 | G67: =IF(ISNUMBER('43_Ratios'!I12),MIN(10,'43_Ratios'!I12),0) -> 6.2086359 | H67: =IF(ISNUMBER('43_Ratios'!J12),MIN(10,'43_Ratios'!J12),0) -> 6.9508813 | I67: =IF(ISNUMBER('43_Ratios'!K12),MIN(10,'43_Ratios'!K12),0) -> 1.7426163 | J67: =IF(ISNUMBER('43_Ratios'!L12),MIN(10,'43_Ratios'!L12),0) -> 2.93831 | ... P67: =IF(ISNUMBER('43_Ratios'!R12),MIN(10,'43_Ratios'!R12),0) -> 5.5199733
B68: Covenant | C68: =DSCR_COV -> 1.3 | D68: =DSCR_COV -> 1.3 | E68: =DSCR_COV -> 1.3 | F68: =DSCR_COV -> 1.3 | G68: =DSCR_COV -> 1.3 | H68: =DSCR_COV -> 1.3 | I68: =DSCR_COV -> 1.3 | J68: =DSCR_COV -> 1.3 | ... P68: =DSCR_COV -> 1.3
B69: Sales | C69: ='24_Revenue'!E40/1000000 -> 0 | D69: ='24_Revenue'!F40/1000000 -> 0 | E69: ='24_Revenue'!G40/1000000 -> 327.43786 | F69: ='24_Revenue'!H40/1000000 -> 0 | G69: ='24_Revenue'!I40/1000000 -> 98.611128 | H69: ='24_Revenue'!J40/1000000 -> 72.314827 | I69: ='24_Revenue'!K40/1000000 -> 0 | J69: ='24_Revenue'!L40/1000000 -> 0 | ... P69: ='24_Revenue'!R40/1000000 -> 0
B70: Rent | C70: ='24_Revenue'!E55/1000000 -> 0 | D70: ='24_Revenue'!F55/1000000 -> 0 | E70: ='24_Revenue'!G55/1000000 -> 0 | F70: ='24_Revenue'!H55/1000000 -> 0 | G70: ='24_Revenue'!I55/1000000 -> 19.287865 | H70: ='24_Revenue'!J55/1000000 -> 27.774526 | I70: ='24_Revenue'!K55/1000000 -> 34.495961 | J70: ='24_Revenue'!L55/1000000 -> 37.255638 | ... P70: ='24_Revenue'!R55/1000000 -> 59.120015
B71: Other | C71: =('24_Revenue'!E57+'24_Revenue'!E59+'24_Revenue'!E60)/1000000 -> 0 | D71: =('24_Revenue'!F57+'24_Revenue'!F59+'24_Revenue'!F60)/1000000 -> 0 | E71: =('24_Revenue'!G57+'24_Revenue'!G59+'24_Revenue'!G60)/1000000 -> 0 | F71: =('24_Revenue'!H57+'24_Revenue'!H59+'24_Revenue'!H60)/1000000 -> 0 | G71: =('24_Revenue'!I57+'24_Revenue'!I59+'24_Revenue'!I60)/1000000 -> 4.2646944 | H71: =('24_Revenue'!J57+'24_Revenue'!J59+'24_Revenue'!J60)/1000000 -> 5.0884938 | I71: =('24_Revenue'!K57+'24_Revenue'!K59+'24_Revenue'!K60)/1000000 -> 5.759423 | J71: =('24_Revenue'!L57+'24_Revenue'!L59+'24_Revenue'!L60)/1000000 -> 6.0803939 | ... P71: =('24_Revenue'!R57+'24_Revenue'!R59+'24_Revenue'!R60)/1000000 -> 6.73557

Sheet 02_Home
B1: Home Estimate | I1: =HYPERLINK("#'00_Start'!A1","◂ Start") -> ◂ Start
B2: የቤት ግንባታ ወጪ ግምት
B3: =PROJ_NAME&" | Scenario: "&SCEN_NAME&" | Mode: "&MODE_NAME -> SAMPLE B — B+G+8 mixed-use building, Addis Ababa | Scenario: Base | Mode: 3 Mixed
B5: =IF(PROJECT_MODE<>0,"Commercial mode is on – this page still shows the cost estimate for the same inputs. · ይህ ገጽ ለተመሳሳይ ግብዓቶች የወጪ ግምቱን ያሳያል።","") -> Commercial mode is on – this page still shows the cost estimate for the same inputs. · ይህ ገጽ ለተመሳሳይ ግብዓቶች የወጪ ግምቱን ያሳያል።
B6: Project · ፕሮጀክት | C6: =PROJ_NAME -> SAMPLE B — B+G+8 mixed-use building, Addis Ababa
B7: Building · ሕንፃ | C7: =BTYPE_CALC&" · "&TEXT(GFA,"#,##0")&" m² gross · "&INDEX(L_FINISH,FIN_IX)&" finish" -> B1+G+8 · 6,400 m² gross · Standard finish
B8: Where & how long · ቦታና ጊዜ | C8: =INDEX(L_LOC,LOC_TYPE)&" · "&CONSTR_EFF&" months of construction" -> Addis Ababa · 30 months of construction
B10: CONSTRUCTION COST · የግንባታ ወጪ | C10: COST PER m² · ዋጋ በካሬ ሜትር | G10: MONTHLY INSTALMENT · ወርሃዊ ክፍያ | I10: FUNDING GAP · የገንዘብ ክፍተት
B11: =CONSTR_COST -> 3.7632566e+08 | C11: =CC_M2 -> 58800.884 | G11: =LN_INSTAL_M -> 472859.07 | I11: =FUND_GAP -> 0
B13: ="Range "&TEXT(CONSTR_COST*(1+EST_LOW)/1000000,"#,##0.0")&" – "&TEXT(CONSTR_COST*(1+EST_HIGH)/1000000,"#,##0.0")&" m" -> Range 338.7 – 432.8 m | C13: ="All-in incl. land & finance: "&TEXT(TDC_M2G,"#,##0") -> All-in incl. land & finance: 86,041 | G13: =IF(HH_INCOME>0,TEXT(AFFORD_PCT,"0%")&" of income · "&AFFORD_TXT,"enter income") -> enter income | I13: =IF(FUND_GAP>0.5,"find more funds","covered · በቂ ነው") -> covered · በቂ ነው
B15: COST BREAKDOWN · የወጪ ክፍፍል | G15: WHERE THE MONEY GOES
B16: Item | C16: ETB | D16: % total
B17: ='22_Capex'!B74 -> Substructure & basement | C17: ='22_Capex'!D74 -> 35120000 | D17: =IF(HOME_TOTAL>0,C17/HOME_TOTAL,0) -> 0.063777962 | E17: መሠረትና ምድር ቤት
B18: ='22_Capex'!B75 -> Frame & envelope | C18: ='22_Capex'!D75 -> 85632000 | D18: =IF(HOME_TOTAL>0,C18/HOME_TOTAL,0) -> 0.15550781 | E18: ፍሬምና ግድግዳ
B19: ='22_Capex'!B76 -> Internal works & finishes | C19: ='22_Capex'!D76 -> 51200000 | D19: =IF(HOME_TOTAL>0,C19/HOME_TOTAL,0) -> 0.092979261 | E19: የውስጥና ማጠናቀቂያ
B20: ='22_Capex'!B77 -> MEP & specialist systems | C20: ='22_Capex'!D77 -> 73160000 | D20: =IF(HOME_TOTAL>0,C20/HOME_TOTAL,0) -> 0.13285865 | E20: ኤሌክትሪክ፣ ቧንቧ፣ ሲስተሞች
B21: ='22_Capex'!B78 -> Preliminaries & external works | C21: ='22_Capex'!D78 -> 22445000 | D21: =IF(HOME_TOTAL>0,C21/HOME_TOTAL,0) -> 0.040760147 | E21: ቅድመ-ሥራና የውጭ ሥራ
B22: ='22_Capex'!B79 -> Escalation & contingency | C22: ='22_Capex'!D79 -> 77311137 | D22: =IF(HOME_TOTAL>0,C22/HOME_TOTAL,0) -> 0.14039712 | E22: የዋጋ ጭማሪና መጠባበቂያ
B23: ='22_Capex'!B80 -> Fees & permits | C23: ='22_Capex'!D80 -> 25457520 | D23: =IF(HOME_TOTAL>0,C23/HOME_TOTAL,0) -> 0.046230888 | E23: ክፍያዎችና ፈቃድ
B24: ='22_Capex'!B81 -> Furniture & FF&E | C24: ='22_Capex'!D81 -> 6000000 | D24: =IF(HOME_TOTAL>0,C24/HOME_TOTAL,0) -> 0.010896007 | E24: የቤት ዕቃዎች
B25: ='22_Capex'!B82 -> Land | C25: ='22_Capex'!D82 -> 150000000 | D25: =IF(HOME_TOTAL>0,C25/HOME_TOTAL,0) -> 0.27240018 | E25: መሬት
B26: ='22_Capex'!B83 -> Finance costs (fees + IDC) | C26: ='22_Capex'!D83 -> 24334774 | D26: =IF(HOME_TOTAL>0,C26/HOME_TOTAL,0) -> 0.044191979 | E26: የብድር ወጪ
B27: TOTAL PROJECT COST · ጠቅላላ | C27: =SUM(C17:C26) -> 5.5066043e+08
B29: PAYING THE CONTRACTOR · ለኮንትራክተር ክፍያ | G29: CASH NEEDED EACH MONTH (S-curve)
B30: Stage | C30: ETB | D30: Cum. % | E30: ≈ month
B31: ='22_Capex'!B87 -> 1 Mobilisation & site set-up | C31: ='22_Capex'!D87 -> 13198869 | D31: =IF(STAGE_TOT>0,SUM($C$31:C31)/STAGE_TOT,0) -> 0.038272219 | E31: =MIN(CONSTR_EFF,COUNTIF('23_Construction'!$E$16:$AZ$16,"<"&(D31-0.0001))+1) -> 5
B32: ='22_Capex'!B88 -> 2 Foundation / substructure | C32: ='22_Capex'!D88 -> 45267995 | D32: =IF(STAGE_TOT>0,SUM($C$31:C32)/STAGE_TOT,0) -> 0.16953397 | E32: =MIN(CONSTR_EFF,COUNTIF('23_Construction'!$E$16:$AZ$16,"<"&(D32-0.0001))+1) -> 10
B33: ='22_Capex'!B89 -> 3 Frame (columns, beams, slabs) | C33: ='22_Capex'!D89 -> 70778934 | D33: =IF(STAGE_TOT>0,SUM($C$31:C33)/STAGE_TOT,0) -> 0.37476874 | E33: =MIN(CONSTR_EFF,COUNTIF('23_Construction'!$E$16:$AZ$16,"<"&(D33-0.0001))+1) -> 14
B34: ='22_Capex'!B90 -> 4 Walls, windows & roof | C34: ='22_Capex'!D90 -> 39596606 | D34: =IF(STAGE_TOT>0,SUM($C$31:C34)/STAGE_TOT,0) -> 0.4895854 | E34: =MIN(CONSTR_EFF,COUNTIF('23_Construction'!$E$16:$AZ$16,"<"&(D34-0.0001))+1) -> 15
B35: ='22_Capex'!B91 -> 5 MEP & internal works | C35: ='22_Capex'!D91 -> 1.1409803e+08 | D35: =IF(STAGE_TOT>0,SUM($C$31:C35)/STAGE_TOT,0) -> 0.82043079 | E35: =MIN(CONSTR_EFF,COUNTIF('23_Construction'!$E$16:$AZ$16,"<"&(D35-0.0001))+1) -> 21
B36: ='22_Capex'!B92 -> 6 Finishes & external works | C36: ='22_Capex'!D92 -> 61927700 | D36: =IF(STAGE_TOT>0,SUM($C$31:C36)/STAGE_TOT,0) -> 1 | E36: =MIN(CONSTR_EFF,COUNTIF('23_Construction'!$E$16:$AZ$16,"<"&(D36-0.0001))+1) -> 30
B37: Retention released after completion | C37: =RET_TOT -> 15966117 | E37: =CONSTR_EFF+RET_REL_M -> 42
B39: FUNDING & HOME LOAN · ገንዘብና ብድር | G39: HOME-LOAN SCHEDULE · የብድር ሰንጠረዥ
B40: Own savings · ቁጠባ | C40: =SAVINGS -> 0 | G40: Year | H40: Interest | I40: Principal | J40: Closing
B41: Family / diaspora · ቤተሰብ | C41: =FAMILY -> 0 | G41: Build | H41: =SUMIFS('27_Loan'!$E$65:$KF$65,'27_Loan'!$E$56:$KF$56,0) -> 17535682 | J41: =SUMIFS('27_Loan'!$E$75:$KF$75,'27_Loan'!$E$55:$KF$55,0) -> 1.3314989e+08
B42: Home loan drawn · የወጣ ብድር | C42: =DEBT_DRAWN -> 1.1561421e+08 | G42: 1 | H42: =SUMIFS('27_Loan'!$E$65:$KF$65,'27_Loan'!$E$56:$KF$56,$G42) -> 14569759 | I42: =SUMIFS('27_Loan'!$E$72:$KF$72,'27_Loan'!$E$56:$KF$56,$G42)+SUMIFS('27_Loan'!$E$74:$KF$74,'27_Loan'!$E$56:$KF$56,$G42) -> 78736994 | J42: =SUMIFS('27_Loan'!$E$75:$KF$75,'27_Loan'!$E$55:$KF$55,12*$G42) -> 54412900
B43: Funding gap · ክፍተት | C43: =FUND_GAP -> 0 | G43: 2 | H43: =SUMIFS('27_Loan'!$E$65:$KF$65,'27_Loan'!$E$56:$KF$56,$G43) -> 7991598.9 | I43: =SUMIFS('27_Loan'!$E$72:$KF$72,'27_Loan'!$E$56:$KF$56,$G43)+SUMIFS('27_Loan'!$E$74:$KF$74,'27_Loan'!$E$56:$KF$56,$G43) -> 32049931 | J43: =SUMIFS('27_Loan'!$E$75:$KF$75,'27_Loan'!$E$55:$KF$55,12*$G43) -> 22362969
B44: Interest rate · ወለድ | C44: =RATE_EFF -> 0.15 | G44: 3 | H44: =SUMIFS('27_Loan'!$E$65:$KF$65,'27_Loan'!$E$56:$KF$56,$G44) -> 3268392.5 | I44: =SUMIFS('27_Loan'!$E$72:$KF$72,'27_Loan'!$E$56:$KF$56,$G44)+SUMIFS('27_Loan'!$E$74:$KF$74,'27_Loan'!$E$56:$KF$56,$G44) -> 1578227.2 | J44: =SUMIFS('27_Loan'!$E$75:$KF$75,'27_Loan'!$E$55:$KF$55,12*$G44) -> 20784742
B45: Tenor after completion (yrs) | C45: =TENOR_Y -> 10 | G45: 4 | H45: =SUMIFS('27_Loan'!$E$65:$KF$65,'27_Loan'!$E$56:$KF$56,$G45) -> 3018006.1 | I45: =SUMIFS('27_Loan'!$E$72:$KF$72,'27_Loan'!$E$56:$KF$56,$G45)+SUMIFS('27_Loan'!$E$74:$KF$74,'27_Loan'!$E$56:$KF$56,$G45) -> 1828613.6 | J45: =SUMIFS('27_Loan'!$E$75:$KF$75,'27_Loan'!$E$55:$KF$55,12*$G45) -> 18956128
B46: Monthly instalment · ወርሃዊ ክፍያ | C46: =LN_INSTAL_M -> 472859.07 | G46: 5 | H46: =SUMIFS('27_Loan'!$E$65:$KF$65,'27_Loan'!$E$56:$KF$56,$G46) -> 2727895.8 | I46: =SUMIFS('27_Loan'!$E$72:$KF$72,'27_Loan'!$E$56:$KF$56,$G46)+SUMIFS('27_Loan'!$E$74:$KF$74,'27_Loan'!$E$56:$KF$56,$G46) -> 2118723.9 | J46: =SUMIFS('27_Loan'!$E$75:$KF$75,'27_Loan'!$E$55:$KF$55,12*$G46) -> 16837404
...

Sheet 10_Inputs
B1: 10 · Inputs – all assumptions | J1: =HYPERLINK("#'00_Start'!A1","◂ Start") -> ◂ Start
B2: ግብዓቶች – ሁሉም ግምቶች
B3: =PROJ_NAME&" | Scenario: "&SCEN_NAME&" | Mode: "&MODE_NAME -> SAMPLE B — B+G+8 mixed-use building, Addis Ababa | Scenario: Base | Mode: 3 Mixed
B6: Input | C6: ግብዓት | D6: Unit | E6: MY PROJECT (your values) | F6: SAMPLE A G+1 house | G6: SAMPLE B B+G+8 mixed | H6: ACTIVE (used by model) | I6: Range name | J6: Notes / source
B7: Blue cells on amber are inputs. Column H picks the data set chosen on the Start sheet (1 = My project, 2 = Sample A, 3 = Sample B). Sample columns are examples – "Sample value — not market advice".
B9: 1. Project | C9: 1. ፕሮጀክት
B10: Project name | C10: የፕሮጀክት ስም | D10: text | E10: My project | F10: SAMPLE A — G+1 family house, Addis Ababa | G10: SAMPLE B — B+G+8 mixed-use building, Addis Ababa | H10: =CHOOSE(DATA_SET,E10,F10,G10) -> SAMPLE B — B+G+8 mixed-use building, Addis Ababa | I10: PROJ_NAME | J10: Shown in every sheet header
B11: Location (sub-city / town) | C11: አካባቢ (ክ/ከተማ / ከተማ) | D11: text | F11: Addis Ababa – Bole sub-city | G11: Addis Ababa – Kirkos sub-city | H11: =CHOOSE(DATA_SET,E11,F11,G11) -> Addis Ababa – Kirkos sub-city | I11: LOCATION | J11: Free text
B12: Location class for cost factor | C12: የቦታ ዓይነት (ለወጪ ማስተካከያ) | D12: list | E12: Addis Ababa | F12: Addis Ababa | G12: Addis Ababa | H12: =IFERROR(MATCH(CHOOSE(DATA_SET,E12,F12,G12),L_LOC,0),1) -> 1 | I12: LOC_TYPE | J12: Regional towns use the regional location factor
B13: Plot area | C13: የቦታ ስፋት | D13: m² | E13: 0 | F13: 300 | G13: 1000 | H13: =CHOOSE(DATA_SET,E13,F13,G13) -> 1000 | I13: PLOT_AREA | J13: From title deed / lease contract
B14: Max floor-area ratio (FAR) permitted | C14: የተፈቀደ የወለል ስፋት ጥምርታ | D14: x | E14: 0 | F14: 1.5 | G14: 8 | H14: =CHOOSE(DATA_SET,E14,F14,G14) -> 8 | I14: FAR | J14: From the city master plan / building permit; 0 = not checked
B15: Construction start date | C15: የግንባታ መጀመሪያ ቀን | D15: date | E15: 46388 | F15: 46388 | G15: 46388 | H15: =CHOOSE(DATA_SET,E15,F15,G15) -> 46388 | I15: START_DATE | J15: First month of construction (budget date for prices)
B16: Construction period | C16: የግንባታ ጊዜ | D16: months | E16: 12 | F16: 14 | G16: 30 | H16: =CHOOSE(DATA_SET,E16,F16,G16) -> 30 | I16: CONSTR_M | J16: 1–48 months; scenario delay months are added
B17: Memo: ETB per USD | C17: ብር በአንድ ዶላር (ማስታወሻ) | D17: ETB/USD | E17: 155 | F17: 155 | G17: 155 | H17: =CHOOSE(DATA_SET,E17,F17,G17) -> 155 | I17: FX_USD | J17: Memo only – the model runs in ETB. Verify current NBE rate
B18: 2. Home estimate card (Mode 0) | C18: 2. የቤት ወጪ ግምት መረጃ (ዓይነት 0)
B19: Building type | C19: የሕንፃው ዓይነት | D19: list | E19: G+1 | F19: G+1 | G19: Other / commercial | H19: =IFERROR(MATCH(CHOOSE(DATA_SET,E19,F19,G19),L_BTYPE,0),1) -> 5 | I19: BLDG_TYPE | J19: Checked against the floors entered in block 3
B20: Basement? | C20: ምድር ቤት አለው? | D20: Y/N | E20: No | F20: No | G20: Yes | H20: =IF(CHOOSE(DATA_SET,E20,F20,G20)="Yes",1,0) -> 1 | I20: BASEMENT_YN | J20: Checked against block 3
B21: Finish level | C21: የማጠናቀቂያ ደረጃ | D21: list | E21: Standard | F21: Standard | G21: Standard | H21: =IFERROR(MATCH(CHOOSE(DATA_SET,E21,F21,G21),L_FINISH,0),1) -> 2 | I21: FINISH | J21: Selects the column of the cost library (block 4)
B22: Household monthly income (for affordability) | C22: የቤተሰብ ወርሃዊ ገቢ | D22: ETB/month | E22: 0 | F22: 300000 | G22: 0 | H22: =CHOOSE(DATA_SET,E22,F22,G22) -> 0 | I22: HH_INCOME | J22: Net income of all earners
B23: Max instalment as % of income | C23: ከገቢ ከፍተኛ የክፍያ ድርሻ | D23: % | E23: 0.35 | F23: 0.35 | G23: 0.35 | H23: =CHOOSE(DATA_SET,E23,F23,G23) -> 0.35 | I23: AFFORD_MAX | J23: Typical bank rule of thumb 30–40%
B24: Estimate range – low side | C24: የግምት ዝቅተኛ ወሰን | D24: % | E24: -0.1 | F24: -0.1 | G24: -0.1 | H24: =CHOOSE(DATA_SET,E24,F24,G24) -> -0.1 | I24: EST_LOW | J24: Applied to construction cost for the low estimate
B25: Estimate range – high side | C25: የግምት ከፍተኛ ወሰን | D25: % | E25: 0.15 | F25: 0.15 | G25: 0.15 | H25: =CHOOSE(DATA_SET,E25,F25,G25) -> 0.15 | I25: EST_HIGH | J25: Applied to construction cost for the high estimate
B26: Own savings available | C26: የራስ ቁጠባ | D26: ETB | E26: 0 | F26: 5000000 | G26: 0 | H26: =CHOOSE(DATA_SET,E26,F26,G26) -> 0 | I26: SAVINGS | J26: Mode 0 funding, drawn first
B27: Family / diaspora contributions | C27: የቤተሰብ / ዳያስፖራ መዋጮ | D27: ETB | E27: 0 | F27: 2500000 | G27: 0 | H27: =CHOOSE(DATA_SET,E27,F27,G27) -> 0 | I27: FAMILY | J27: Mode 0 funding, drawn after savings
B28: Home loan amount (maximum) | C28: የቤት ብድር መጠን | D28: ETB | E28: 0 | F28: 7000000 | G28: 0 | H28: =CHOOSE(DATA_SET,E28,F28,G28) -> 0 | I28: HOME_LOAN | J28: Mode 0: bank home-loan limit. Uses the loan terms in block 9
B29: I may rent out part of the house | C29: የቤቱን ከፊል ለማከራየት እችላለሁ | D29: Y/N | E29: No | F29: No | G29: No | H29: =IF(CHOOSE(DATA_SET,E29,F29,G29)="Yes",1,0) -> 0 | I29: RENT_HOME_F | J29: Upgrade path inside Mode 0: adds rent, payback and yield
B30: Area rented out | C30: የሚከራየው ስፋት | D30: m² | E30: 0 | F30: 60 | G30: 0 | H30: =CHOOSE(DATA_SET,E30,F30,G30) -> 0 | I30: RENT_HOME_AREA | J30: e.g. ground-floor unit or service quarter
B31: Expected rent for that part (today's prices) | C31: የሚጠበቅ ወርሃዊ ኪራይ | D31: ETB/month | E31: 0 | F31: 25000 | G31: 0 | H31: =CHOOSE(DATA_SET,E31,F31,G31) -> 0 | I31: RENT_HOME_MONTHLY | J31: Escalated with rent escalation (block 7)
B32: 3. Area programme – gross floor area by floor | C32: 3. የወለል ስፋት በፎቅ
B33: Basement 2 – gross area | C33: ምድር ቤት 2 – ጠቅላላ ስፋት | D33: m² | E33: 0 | F33: 0 | G33: 0 | H33: =CHOOSE(DATA_SET,E33,F33,G33) -> 0 | I33: FL_A1 | J33: Gross floor area incl. walls & common areas
B34: Basement 1 – gross area | C34: ምድር ቤት 1 – ጠቅላላ ስፋት | D34: m² | E34: 0 | F34: 0 | G34: 900 | H34: =CHOOSE(DATA_SET,E34,F34,G34) -> 900 | I34: FL_A2 | J34: Gross floor area incl. walls & common areas
B35: Ground floor – gross area | C35: ምድር ወለል – ጠቅላላ ስፋት | D35: m² | E35: 0 | F35: 130 | G35: 650 | H35: =CHOOSE(DATA_SET,E35,F35,G35) -> 650 | I35: FL_A3 | J35: Gross floor area incl. walls & common areas
B36: Floor 1 – gross area | C36: 1ኛ ፎቅ – ጠቅላላ ስፋት | D36: m² | E36: 0 | F36: 120 | G36: 650 | H36: =CHOOSE(DATA_SET,E36,F36,G36) -> 650 | I36: FL_A4 | J36: Gross floor area incl. walls & common areas
B37: Floor 2 – gross area | C37: 2ኛ ፎቅ – ጠቅላላ ስፋት | D37: m² | E37: 0 | F37: 0 | G37: 600 | H37: =CHOOSE(DATA_SET,E37,F37,G37) -> 600 | I37: FL_A5 | J37: Gross floor area incl. walls & common areas
B38: Floor 3 – gross area | C38: 3ኛ ፎቅ – ጠቅላላ ስፋት | D38: m² | E38: 0 | F38: 0 | G38: 600 | H38: =CHOOSE(DATA_SET,E38,F38,G38) -> 600 | I38: FL_A6 | J38: Gross floor area incl. walls & common areas
B39: Floor 4 – gross area | C39: 4ኛ ፎቅ – ጠቅላላ ስፋት | D39: m² | E39: 0 | F39: 0 | G39: 600 | H39: =CHOOSE(DATA_SET,E39,F39,G39) -> 600 | I39: FL_A7 | J39: Gross floor area incl. walls & common areas
B40: Floor 5 – gross area | C40: 5ኛ ፎቅ – ጠቅላላ ስፋት | D40: m² | E40: 0 | F40: 0 | G40: 600 | H40: =CHOOSE(DATA_SET,E40,F40,G40) -> 600 | I40: FL_A8 | J40: Gross floor area incl. walls & common areas
B41: Floor 6 – gross area | C41: 6ኛ ፎቅ – ጠቅላላ ስፋት | D41: m² | E41: 0 | F41: 0 | G41: 600 | H41: =CHOOSE(DATA_SET,E41,F41,G41) -> 600 | I41: FL_A9 | J41: Gross floor area incl. walls & common areas
B42: Floor 7 – gross area | C42: 7ኛ ፎቅ – ጠቅላላ ስፋት | D42: m² | E42: 0 | F42: 0 | G42: 600 | H42: =CHOOSE(DATA_SET,E42,F42,G42) -> 600 | I42: FL_A10 | J42: Gross floor area incl. walls & common areas
B43: Floor 8 – gross area | C43: 8ኛ ፎቅ – ጠቅላላ ስፋት | D43: m² | E43: 0 | F43: 0 | G43: 600 | H43: =CHOOSE(DATA_SET,E43,F43,G43) -> 600 | I43: FL_A11 | J43: Gross floor area incl. walls & common areas
...

Sheet 11_Scenarios
B1: 11 · Scenarios – Base / Upside / Downside / Lender | J1: =HYPERLINK("#'00_Start'!A1","◂ Start") -> ◂ Start
B2: ሁኔታዎች – መሠረታዊ፣ ብሩህ፣ አስቸጋሪ፣ ባንክ
B3: =PROJ_NAME&" | Scenario: "&SCEN_NAME&" | Mode: "&MODE_NAME -> SAMPLE B — B+G+8 mixed-use building, Addis Ababa | Scenario: Base | Mode: 3 Mixed
B10: Scenario adjustments (applied on top of the Inputs). Active = CHOOSE(SCEN, Base, Upside, Downside, Lender) | C10: የሁኔታ ማስተካከያዎች
B11: Driver | C11: ነጂ | D11: Unit | E11: Base | F11: Upside | G11: Downside | H11: Lender | I11: ACTIVE | J11: Name
B12: Sale price | C12: የሽያጭ ዋጋ | D12: % | E12: 0 | F12: 0.1 | G12: -0.1 | H12: -0.15 | I12: =CHOOSE(SCEN,E12,F12,G12,H12) -> 0 | J12: SC_PRICE
B13: Rent | C13: ኪራይ | D13: % | E13: 0 | F13: 0.1 | G13: -0.1 | H13: -0.15 | I13: =CHOOSE(SCEN,E13,F13,G13,H13) -> 0 | J13: SC_RENT
B14: Occupancy (points) | C14: የተያዘ መጠን | D14: pts | E14: 0 | F14: 0.03 | G14: -0.1 | H14: -0.15 | I14: =CHOOSE(SCEN,E14,F14,G14,H14) -> 0 | J14: SC_OCC
B15: Construction cost | C15: የግንባታ ወጪ | D15: % | E15: 0 | F15: -0.05 | G15: 0.1 | H15: 0.15 | I15: =CHOOSE(SCEN,E15,F15,G15,H15) -> 0 | J15: SC_COST
B16: Construction delay | C16: የግንባታ መዘግየት | D16: months | E16: 0 | F16: 0 | G16: 6 | H16: 6 | I16: =CHOOSE(SCEN,E16,F16,G16,H16) -> 0 | J16: SC_DELAY
B17: Interest rate (points) | C17: የወለድ መጠን | D17: pts | E17: 0 | F17: -0.01 | G17: 0.02 | H17: 0.03 | I17: =CHOOSE(SCEN,E17,F17,G17,H17) -> 0 | J17: SC_RATE
B18: Presales achieved | C18: ቅድመ-ሽያጭ | D18: % | E18: 0 | F18: 0.1 | G18: -0.25 | H18: -0.4 | I18: =CHOOSE(SCEN,E18,F18,G18,H18) -> 0 | J18: SC_PRESALE
B19: Exit cap rate (points) | C19: የመውጫ ካፕ ሬት | D19: pts | E19: 0 | F19: -0.005 | G19: 0.01 | H19: 0.015 | I19: =CHOOSE(SCEN,E19,F19,G19,H19) -> 0 | J19: SC_EXITCAP
B20: Operating costs | C20: የሥራ ማስኬጃ ወጪ | D20: % | E20: 0 | F20: -0.05 | G20: 0.1 | H20: 0.15 | I20: =CHOOSE(SCEN,E20,F20,G20,H20) -> 0 | J20: SC_OPEX
B21: Cost escalation (points) | C21: የዋጋ ጭማሪ | D21: pts | E21: 0 | F21: -0.02 | G21: 0.05 | H21: 0.05 | I21: =CHOOSE(SCEN,E21,F21,G21,H21) -> 0 | J21: SC_ESC
B22: Rent escalation (points) | C22: የኪራይ ጭማሪ | D22: pts | E22: 0 | F22: 0.01 | G22: -0.02 | H22: -0.03 | I22: =CHOOSE(SCEN,E22,F22,G22,H22) -> 0 | J22: SC_RESC
B23: Sale price escalation (points) | C23: የሽያጭ ዋጋ ጭማሪ | D23: pts | E23: 0 | F23: 0.02 | G23: -0.03 | H23: -0.05 | I23: =CHOOSE(SCEN,E23,F23,G23,H23) -> 0 | J23: SC_PESC
... B26: Sales absorption speed | C26: የሽያጭ ፍጥነት | D26: % | E26: 0 | F26: 0.2 | G26: -0.3 | H26: -0.5 | I26: =CHOOSE(SCEN,E26,F26,G26,H26) -> 0 | J26: SC_ABS
B28: Effective drivers used by the engine (scenario × flex cell) | C28: ሞዴሉ የሚጠቀማቸው ውጤታማ ነጂዎች
B29: Active scenario (1–4) | D29: =IF(SCEN_OVR>0,SCEN_OVR,SCEN_SEL) -> 1
B30: Sale price factor | D30: =(1+SC_PRICE)*FLX_PRICE -> 1
B31: Rent factor | D31: =(1+SC_RENT)*FLX_RENT -> 1
B32: Construction cost factor | D32: =(1+SC_COST)*FLX_COST -> 1
B33: Opex factor | D33: =(1+SC_OPEX)*FLX_OPEX -> 1
B34: Occupancy points added | D34: =SC_OCC -> 0
B35: Occupancy factor | D35: =FLX_OCC -> 1
B36: Interest rate points added | D36: =SC_RATE -> 0
B37: Interest rate factor | D37: =FLX_RATE -> 1
B38: Effective base interest rate | D38: =MAX(0,(RATE+D_RATE_ADD)*D_RATE_F) -> 0.15
B39: Effective construction months (incl. delay) | D39: =MAX(1,MIN(48,ROUND(CONSTR_M+SC_DELAY+FLX_DELAY,0))) -> 30
B40: Presale factor | D40: =MAX(0,1+SC_PRESALE) -> 1
B41: Effective exit cap rate | D41: =MAX(0.001,EXIT_CAP+SC_EXITCAP) -> 0.09
B42: Effective cost escalation | D42: =ESC_PA+SC_ESC -> 0.15
B43: Effective rent escalation | D43: =RENT_ESC+SC_RESC -> 0.08
B44: Effective sale-price escalation | D44: =PRICE_ESC+SC_PESC -> 0.1
B45: Effective default allowance | D45: =MIN(1,MAX(0,DEFAULT_PCT+SC_DEFAULT)) -> 0.02
B46: Effective project discount rate | D46: =DISC+SC_DISC -> 0.18
B47: Effective cost of equity | D47: =COE+SC_DISC -> 0.22
B48: Absorption factor | D48: =MAX(0,1+SC_ABS) -> 1

Sheet 12_TaxLaw
B1: 12 · Tax law register | G1: =HYPERLINK("#'00_Start'!A1","◂ Start") -> ◂ Start
B2: የግብር ሕግ መዝገብ
B3: =PROJ_NAME&" | Scenario: "&SCEN_NAME&" | Mode: "&MODE_NAME -> SAMPLE B — B+G+8 mixed-use building, Addis Ababa | Scenario: Base | Mode: 3 Mixed
B10: Rates used by the model and their statutory source – YOU MUST CONFIRM CURRENT RATES BEFORE USE | C10: የግብር መጣኔዎች
B11: Item | C11: Rate used | D11: Statutory source | E11: Last verified | F11: Verify before use | G11: Model name
B12: Corporate income tax | C12: =CIT -> 0.3 | D12: Federal Income Tax Proclamation No. 979/2016, Art. 19(1) – 30% for bodies | E12: 46300 | F12: YES – verify | G12: CIT
B13: Tax depreciation – buildings | C13: =TAXDEP_BLD -> 0.05 | D13: Proc. 979/2016, Art. 25 & Income Tax Regulation No. 410/2017 – buildings 5% straight line | E13: 46300 | F13: YES – verify | G13: TAXDEP_BLD
B14: Tax depreciation – plant & equipment | C14: =TAXDEP_PLANT -> 0.2 | D14: Proc. 979/2016, Art. 25 – other business assets 20% (pool / diminishing value per spec) | E14: 46300 | F14: YES – verify | G14: TAXDEP_PLANT
B15: Loss carry-forward period | C15: =LCF_YEARS -> 5 | D15: Proc. 979/2016, Art. 26 – losses carried forward up to 5 years (limits on number of carry-forwards apply) | E15: 46300 | F15: YES – verify | G15: LCF_YEARS
B16: Loss offset cap | C16: =LCF_CAP -> 1 | D16: Model assumption – no statutory cap identified; set below 100% if a cap applies | E16: 46300 | F16: YES – verify | G16: LCF_CAP
B17: VAT – standard rate | C17: =VAT_R -> 0.15 | D17: Value Added Tax Proclamation No. 1341/2024 – 15% standard rate | E17: 46300 | F17: YES – verify | G17: VAT_R
B18: VAT on sale of buildings (share taxable) | C18: =VAT_SALES_PCT -> 0 | D18: Proc. 1341/2024 – exemptions for residential dwellings; confirm treatment of new-build sales | E18: 46300 | F18: YES – verify | G18: VAT_SALES_PCT
B19: VAT on rent (share taxable) | C19: =RENT_VAT_PCT -> 1 | D19: Proc. 1341/2024 – residential rent exempt; commercial rent taxable | E19: 46300 | F19: YES – verify | G19: RENT_VAT_PCT
B20: Undistributed profits tax | C20: =UPT_R -> 0.1 | D20: Proc. 979/2016, Art. 55 – undistributed / non-reinvested profits treated as dividend (10%) | E20: 46300 | F20: YES – verify | G20: UPT_R
B21: Dividend withholding tax | C21: =DIV_WHT -> 0.1 | D21: Proc. 979/2016, Art. 55 – 10% on dividends | E21: 46300 | F21: YES – verify | G21: DIV_WHT
B22: Legal reserve transfer | C22: =LR_PCT -> 0.05 | D22: Commercial Code of Ethiopia, Proc. No. 1243/2021, Art. 434 – 5% of profits | E22: 46300 | F22: YES – verify | G22: LR_PCT
B23: Legal reserve cap | C23: =LR_CAP -> 0.1 | D23: Commercial Code, Art. 434 – until reserve reaches 10% of capital | E23: 46300 | F23: YES – verify | G23: LR_CAP
B24: Property tax | C24: =PROPTAX_PCT -> 0.001 | D24: City property-tax proclamation (Addis Ababa) – rate and base to be confirmed | E24: 46300 | F24: YES – verify | G24: PROPTAX_PCT
B25: Land lease down payment | C25: =LEASE_DP -> 0.1 | D25: Urban Lands Lease Holding Proclamation No. 721/2011 and city regulations – minimum down payment | E25: 46300 | F25: YES – verify | G25: LEASE_DP
B26: Land lease instalment period | C26: =LEASE_N -> 30 | D26: Proc. 721/2011 – instalment period per lease contract | E26: 46300 | F26: YES – verify | G26: LEASE_N
B27: Interest on unpaid lease | C27: =LEASE_INT -> 0.07 | D27: Lease contract / city regulation – usually linked to the NBE / bank lending rate | E27: 46300 | F27: YES – verify | G27: LEASE_INT
B29: Note: 'Last verified' records a desk review on that date, not confirmation against the official gazette. Tax law in Ethiopia changes frequently – confirm every rate with the Ministry of Revenue, the city administration or a licensed tax adviser before relying on results.
B30: ማሳሰቢያ፡ ሞዴሉን ከመጠቀምዎ በፊት ሁሉንም የግብር መጣኔዎች ከገቢዎች ሚኒስቴር ወይም ፈቃድ ካለው የግብር አማካሪ ያረጋግጡ።

Sheet 20_Timeline
B1: 20 · Timeline & flags | R1: =HYPERLINK("#'00_Start'!A1","◂ Start") -> ◂ Start
B2: የጊዜ ሰሌዳና ጠቋሚዎች
B3: =PROJ_NAME&" | Scenario: "&SCEN_NAME&" | Mode: "&MODE_NAME -> SAMPLE B — B+G+8 mixed-use building, Addis Ababa | Scenario: Base | Mode: 3 Mixed
B6: Period | D6: Total | E6: =E12 -> C1 | F6: =F12 -> C2 | G6: =G12 -> C3 | H6: =H12 -> C4 | I6: =I12 -> O1 | J6: =J12 -> O2 | K6: =K12 -> O3 | L6: =L12 -> O4 | ... R6: =R12 -> O10
B7: Period end (Gregorian) | E7: =E22 -> 46752 | F7: =F22 -> 47118 | G7: =G22 -> 47299 | H7: =H22 -> 47299 | I7: =I22 -> 47664 | J7: =J22 -> 48029 | K7: =K22 -> 48395 | L7: =L22 -> 48760 | ... R7: =R22 -> 50951
B8: Ethiopian calendar year | E8: =E26 -> EC 2020 | F8: =F26 -> EC 2021 | G8: =G26 -> EC 2021 | H8: =H26 -> EC 2021 | I8: =I26 -> EC 2022 | J8: =J26 -> EC 2023 | K8: =K26 -> EC 2024 | L8: =L26 -> EC 2025 | ... R8: =R26 -> EC 2031
B10: Annual periods: C1–C4 construction years, O1–O10 operating years | C10: ዓመታዊ ጊዜያት
B11: Period number | C11: no. | E11: 1 | F11: 2 | G11: 3 | H11: 4 | I11: 5 | J11: 6 | K11: 7 | L11: 8 | M11: 9 | N11: 10 | O11: 11 | P11: 12 | Q11: 13 | R11: 14
B12: Period label | E12: C1 | F12: C2 | G12: C3 | H12: C4 | I12: O1 | J12: O2 | K12: O3 | L12: O4 | M12: O5 | N12: O6 | O12: O7 | P12: O8 | Q12: O9 | R12: O10
B13: Construction-year index | C13: no. | E13: 1 | F13: 2 | G13: 3 | H13: 4 | I13: 0 | J13: 0 | K13: 0 | L13: 0 | M13: 0 | N13: 0 | O13: 0 | P13: 0 | Q13: 0 | R13: 0
B14: Operating-year index | C14: no. | E14: 0 | F14: 0 | G14: 0 | H14: 0 | I14: 1 | J14: 2 | K14: 3 | L14: 4 | M14: 5 | N14: 6 | O14: 7 | P14: 8 | Q14: 9 | R14: 10
B15: Months in period | C15: months | D15: =SUM(E15:R15) -> 150 | E15: =MAX(0,MIN(12,CONSTR_EFF-12*(E13-1))) -> 12 | F15: =MAX(0,MIN(12,CONSTR_EFF-12*(F13-1))) -> 12 | G15: =MAX(0,MIN(12,CONSTR_EFF-12*(G13-1))) -> 6 | H15: =MAX(0,MIN(12,CONSTR_EFF-12*(H13-1))) -> 0 | I15: 12 | J15: 12 | K15: 12 | L15: 12 | M15: 12 | N15: 12 | O15: 12 | P15: 12 | Q15: 12 | R15: 12
B16: Period active flag | C16: flag | E16: =IF(E15>0,1,0) -> 1 | F16: =IF(F15>0,1,0) -> 1 | G16: =IF(G15>0,1,0) -> 1 | H16: =IF(H15>0,1,0) -> 0 | I16: =IF(I15>0,1,0) -> 1 | J16: =IF(J15>0,1,0) -> 1 | K16: =IF(K15>0,1,0) -> 1 | L16: =IF(L15>0,1,0) -> 1 | ... R16: =IF(R15>0,1,0) -> 1
B17: Construction flag | C17: flag | D17: =SUM(E17:R17) -> 3 | E17: =IF(AND(E13>0,E15>0),1,0) -> 1 | F17: =IF(AND(F13>0,F15>0),1,0) -> 1 | G17: =IF(AND(G13>0,G15>0),1,0) -> 1 | H17: =IF(AND(H13>0,H15>0),1,0) -> 0 | I17: 0 | J17: 0 | K17: 0 | L17: 0 | M17: 0 | N17: 0 | O17: 0 | P17: 0 | Q17: 0 | R17: 0
B18: Operating flag | C18: flag | D18: =SUM(E18:R18) -> 10 | E18: =IF(AND(E14>=1,E14<=OPS_YEARS),1,0) -> 0 | F18: =IF(AND(F14>=1,F14<=OPS_YEARS),1,0) -> 0 | G18: =IF(AND(G14>=1,G14<=OPS_YEARS),1,0) -> 0 | H18: =IF(AND(H14>=1,H14<=OPS_YEARS),1,0) -> 0 | I18: =IF(AND(I14>=1,I14<=OPS_YEARS),1,0) -> 1 | J18: =IF(AND(J14>=1,J14<=OPS_YEARS),1,0) -> 1 | K18: =IF(AND(K14>=1,K14<=OPS_YEARS),1,0) -> 1 | L18: =IF(AND(L14>=1,L14<=OPS_YEARS),1,0) -> 1 | ... R18: =IF(AND(R14>=1,R14<=OPS_YEARS),1,0) -> 1
B19: Completion (COD) period flag | C19: flag | D19: =SUM(E19:R19) -> 1 | E19: =IF(AND(E15>0,MIN(12*E13,CONSTR_EFF)=CONSTR_EFF),1,0) -> 0 | F19: =IF(AND(F15>0,MIN(12*F13,CONSTR_EFF)=CONSTR_EFF),1,0) -> 0 | G19: =IF(AND(G15>0,MIN(12*G13,CONSTR_EFF)=CONSTR_EFF),1,0) -> 1 | H19: =IF(AND(H15>0,MIN(12*H13,CONSTR_EFF)=CONSTR_EFF),1,0) -> 0 | I19: 0 | J19: 0 | K19: 0 | L19: 0 | M19: 0 | N19: 0 | O19: 0 | P19: 0 | Q19: 0 | R19: 0
B20: First month index | C20: no. | E20: =12*(E13-1)+1 -> 1 | F20: =12*(F13-1)+1 -> 13 | G20: =12*(G13-1)+1 -> 25 | H20: =12*(H13-1)+1 -> 37 | I20: =CONSTR_EFF+12*(I14-1)+1 -> 31 | J20: =CONSTR_EFF+12*(J14-1)+1 -> 43 | K20: =CONSTR_EFF+12*(K14-1)+1 -> 55 | L20: =CONSTR_EFF+12*(L14-1)+1 -> 67 | M20: =CONSTR_EFF+12*(M14-1)+1 -> 79 | N20: =CONSTR_EFF+12*(N14-1)+1 -> 91 | O20: =CONSTR_EFF+12*(O14-1)+1 -> 103 | P20: =CONSTR_EFF+12*(P14-1)+1 -> 115 | ... R20: =CONSTR_EFF+12*(R14-1)+1 -> 139
B21: Last month index | C21: no. | E21: =MIN(12*E13,CONSTR_EFF) -> 12 | F21: =MIN(12*F13,CONSTR_EFF) -> 24 | G21: =MIN(12*G13,CONSTR_EFF) -> 30 | H21: =MIN(12*H13,CONSTR_EFF) -> 30 | I21: =CONSTR_EFF+12*I14 -> 42 | J21: =CONSTR_EFF+12*J14 -> 54 | K21: =CONSTR_EFF+12*K14 -> 66 | L21: =CONSTR_EFF+12*L14 -> 78 | M21: =CONSTR_EFF+12*M14 -> 90 | N21: =CONSTR_EFF+12*N14 -> 102 | O21: =CONSTR_EFF+12*O14 -> 114 | P21: =CONSTR_EFF+12*P14 -> 126 | ... R21: =CONSTR_EFF+12*R14 -> 150
B22: Period end date | C22: date | E22: =EDATE(START_DATE,E21)-1 -> 46752 | F22: =EDATE(START_DATE,F21)-1 -> 47118 | G22: =EDATE(START_DATE,G21)-1 -> 47299 | H22: =EDATE(START_DATE,H21)-1 -> 47299 | I22: =EDATE(START_DATE,I21)-1 -> 47664 | J22: =EDATE(START_DATE,J21)-1 -> 48029 | K22: =EDATE(START_DATE,K21)-1 -> 48395 | L22: =EDATE(START_DATE,L21)-1 -> 48760 | ... R22: =EDATE(START_DATE,R21)-1 -> 50951
B23: Years from start (end of period) | C23: years | E23: =(E22+1-START_DATE)/365 -> 1 | F23: =(F22+1-START_DATE)/365 -> 2.0027397 | G23: =(G22+1-START_DATE)/365 -> 2.4986301 | H23: =(H22+1-START_DATE)/365 -> 2.4986301 | I23: =(I22+1-START_DATE)/365 -> 3.4986301 | J23: =(J22+1-START_DATE)/365 -> 4.4986301 | K23: =(K22+1-START_DATE)/365 -> 5.5013699 | L23: =(L22+1-START_DATE)/365 -> 6.5013699 | ... R23: =(R22+1-START_DATE)/365 -> 12.50411
B24: Period length | C24: years | D24: =SUM(E24:R24) -> 12.5 | E24: =E15/12 -> 1 | F24: =F15/12 -> 1 | G24: =G15/12 -> 0.5 | H24: =H15/12 -> 0 | I24: =I15/12 -> 1 | J24: =J15/12 -> 1 | K24: =K15/12 -> 1 | L24: =L15/12 -> 1 | ... R24: =R15/12 -> 1
B25: Gregorian year (period end) | E25: ="GC "&YEAR(E22) -> GC 2027 | F25: ="GC "&YEAR(F22) -> GC 2028 | G25: ="GC "&YEAR(G22) -> GC 2029 | H25: ="GC "&YEAR(H22) -> GC 2029 | I25: ="GC "&YEAR(I22) -> GC 2030 | J25: ="GC "&YEAR(J22) -> GC 2031 | K25: ="GC "&YEAR(K22) -> GC 2032 | L25: ="GC "&YEAR(L22) -> GC 2033 | ... R25: ="GC "&YEAR(R22) -> GC 2039
B26: Ethiopian calendar year (period end) | E26: ="EC "&(YEAR(E22)-8+IF(E22>=DATE(YEAR(E22),9,11),1,0)) -> EC 2020 | F26: ="EC "&(YEAR(F22)-8+IF(F22>=DATE(YEAR(F22),9,11),1,0)) -> EC 2021 | G26: ="EC "&(YEAR(G22)-8+IF(G22>=DATE(YEAR(G22),9,11),1,0)) -> EC 2021 | H26: ="EC "&(YEAR(H22)-8+IF(H22>=DATE(YEAR(H22),9,11),1,0)) -> EC 2021 | I26: ="EC "&(YEAR(I22)-8+IF(I22>=DATE(YEAR(I22),9,11),1,0)) -> EC 2022 | J26: ="EC "&(YEAR(J22)-8+IF(J22>=DATE(YEAR(J22),9,11),1,0)) -> EC 2023 | K26: ="EC "&(YEAR(K22)-8+IF(K22>=DATE(YEAR(K22),9,11),1,0)) -> EC 2024 | L26: ="EC "&(YEAR(L22)-8+IF(L22>=DATE(YEAR(L22),9,11),1,0)) -> EC 2025 | ... R26: ="EC "&(YEAR(R22)-8+IF(R22>=DATE(YEAR(R22),9,11),1,0)) -> EC 2031
B27: Discount factor @ project rate | C27: x | E27: =(1+DISC_EFF)^(-E23) -> 0.84745763 | F27: =(1+DISC_EFF)^(-F23) -> 0.71785883 | G27: =(1+DISC_EFF)^(-G23) -> 0.66129228 | H27: =(1+DISC_EFF)^(-H23) -> 0.66129228 | I27: =(1+DISC_EFF)^(-I23) -> 0.56041718 | J27: =(1+DISC_EFF)^(-J23) -> 0.47492982 | K27: =(1+DISC_EFF)^(-K23) -> 0.40230042 | L27: =(1+DISC_EFF)^(-L23) -> 0.34093256 | ... R27: =(1+DISC_EFF)^(-R23) -> 0.12623492
B28: Discount factor @ cost of equity | C28: x | E28: =(1+COE_EFF)^(-E23) -> 0.81967213 | F28: =(1+COE_EFF)^(-F23) -> 0.67149647 | G28: =(1+COE_EFF)^(-G23) -> 0.60844135 | H28: =(1+COE_EFF)^(-H23) -> 0.60844135 | I28: =(1+COE_EFF)^(-I23) -> 0.49872242 | J28: =(1+COE_EFF)^(-J23) -> 0.40878887 | K28: =(1+COE_EFF)^(-K23) -> 0.33489035 | L28: =(1+COE_EFF)^(-L23) -> 0.27450028 | ... R28: =(1+COE_EFF)^(-R23) -> 0.083204576
B30: Key timing scalars | C30: ቁልፍ የጊዜ መረጃዎች
B31: Operating horizon (fixed design horizon) | C31: years | D31: 10 | E31: Statements always show C1–C4 + O1–O10
B32: Number of construction periods used | C32: no. | D32: =ROUNDUP(CONSTR_EFF/12,0) -> 3
B33: Completion (COD) date | C33: date | D33: =EDATE(START_DATE,CONSTR_EFF)-1 -> 47299
B34: End of operating horizon (O10) | C34: date | D34: =EDATE(START_DATE,CONSTR_EFF+12*OPS_YEARS)-1 -> 50951
B36: Monthly timeline (construction up to 48 months + 240 months of loan life) | C36: ወርሃዊ የጊዜ ሰሌዳ
B37: Month index t | C37: no. | E37: 1 | F37: 2 | G37: 3 | H37: 4 | I37: 5 | J37: 6 | K37: 7 | L37: 8 | M37: 9 | N37: 10 | O37: 11 | P37: 12 | Q37: 13 | R37: 14 | S37: 15 | T37: 16 | U37: 17 | V37: 18 | W37: 19 | X37: 20 | Y37: 21 | Z37: 22 | AA37: 23 | AB37: 24 | AC37: 25 | AD37: 26 | AE37: 27 | AF37: 28 | AG37: 29 | AH37: 30 | AI37: 31 | AJ37: 32 | AK37: 33 | AL37: 34 | AM37: 35 | AN37: 36 | AO37: 37 | AP37: 38 | AQ37: 39 | AR37: 40 | AS37: 41 | AT37: 42 | AU37: 43 | AV37: 44 | AW37: 45 | AX37: 46 | AY37: 47 | AZ37: 48 | BA37: 49 | BB37: 50 | BC37: 51 | BD37: 52 | BE37: 53 | BF37: 54 | BG37: 55 | BH37: 56 | BI37: 57 | BJ37: 58 | BK37: 59 | BL37: 60 | BM37: 61 | BN37: 62 | BO37: 63 | BP37: 64 | BQ37: 65 | BR37: 66 | BS37: 67 | BT37: 68 | BU37: 69 | BV37: 70 | BW37: 71 | BX37: 72 | BY37: 73 | BZ37: 74 | CA37: 75 | CB37: 76 | CC37: 77 | CD37: 78 | CE37: 79 | CF37: 80 | CG37: 81 | CH37: 82 | CI37: 83 | CJ37: 84 | CK37: 85 | CL37: 86 | CM37: 87 | CN37: 88 | CO37: 89 | CP37: 90 | CQ37: 91 | CR37: 92 | CS37: 93 | CT37: 94 | CU37: 95 | CV37: 96 | CW37: 97 | CX37: 98 | CY37: 99 | CZ37: 100 | DA37: 101 | DB37: 102 | DC37: 103 | DD37: 104 | DE37: 105 | DF37: 106 | DG37: 107 | DH37: 108 | DI37: 109 | DJ37: 110 | DK37: 111 | DL37: 112 | DM37: 113 | DN37: 114 | DO37: 115 | DP37: 116 | DQ37: 117 | DR37: 118 | DS37: 119 | DT37: 120 | DU37: 121 | DV37: 122 | DW37: 123 | DX37: 124 | DY37: 125 | DZ37: 126 | EA37: 127 | EB37: 128 | EC37: 129 | ED37: 130 | EE37: 131 | EF37: 132 | EG37: 133 | EH37: 134 | EI37: 135 | EJ37: 136 | EK37: 137 | EL37: 138 | EM37: 139 | EN37: 140 | EO37: 141 | EP37: 142 | EQ37: 143 | ER37: 144 | ES37: 145 | ET37: 146 | EU37: 147 | EV37: 148 | EW37: 149 | EX37: 150 | EY37: 151 | EZ37: 152 | FA37: 153 | FB37: 154 | FC37: 155 | FD37: 156 | FE37: 157 | FF37: 158 | FG37: 159 | FH37: 160 | FI37: 161 | FJ37: 162 | FK37: 163 | FL37: 164 | FM37: 165 | FN37: 166 | FO37: 167 | FP37: 168 | FQ37: 169 | FR37: 170 | FS37: 171 | FT37: 172 | FU37: 173 | FV37: 174 | FW37: 175 | FX37: 176 | FY37: 177 | FZ37: 178 | GA37: 179 | GB37: 180 | GC37: 181 | GD37: 182 | GE37: 183 | GF37: 184 | GG37: 185 | GH37: 186 | GI37: 187 | GJ37: 188 | GK37: 189 | GL37: 190 | GM37: 191 | GN37: 192 | GO37: 193 | GP37: 194 | GQ37: 195 | GR37: 196 | GS37: 197 | GT37: 198 | GU37: 199 | GV37: 200 | GW37: 201 | GX37: 202 | GY37: 203 | GZ37: 204 | HA37: 205 | HB37: 206 | HC37: 207 | HD37: 208 | HE37: 209 | HF37: 210 | HG37: 211 | HH37: 212 | HI37: 213 | HJ37: 214 | HK37: 215 | HL37: 216 | HM37: 217 | HN37: 218 | HO37: 219 | HP37: 220 | HQ37: 221 | HR37: 222 | HS37: 223 | HT37: 224 | HU37: 225 | HV37: 226 | HW37: 227 | HX37: 228 | HY37: 229 | HZ37: 230 | IA37: 231 | IB37: 232 | IC37: 233 | ID37: 234 | IE37: 235 | IF37: 236 | IG37: 237 | IH37: 238 | II37: 239 | IJ37: 240 | IK37: 241 | IL37: 242 | IM37: 243 | IN37: 244 | IO37: 245 | IP37: 246 | IQ37: 247 | IR37: 248 | IS37: 249 | IT37: 250 | IU37: 251 | IV37: 252 | IW37: 253 | IX37: 254 | IY37: 255 | IZ37: 256 | JA37: 257 | JB37: 258 | JC37: 259 | JD37: 260 | JE37: 261 | JF37: 262 | JG37: 263 | JH37: 264 | JI37: 265 | JJ37: 266 | JK37: 267 | JL37: 268 | JM37: 269 | JN37: 270 | JO37: 271 | JP37: 272 | JQ37: 273 | JR37: 274 | JS37: 275 | JT37: 276 | JU37: 277 | JV37: 278 | JW37: 279 | JX37: 280 | JY37: 281 | JZ37: 282 | KA37: 283 | KB37: 284 | KC37: 285 | KD37: 286 | KE37: 287 | KF37: 288
B38: Month start date | C38: date | E38: =EDATE(START_DATE,E37-1) -> 46388 | F38: =EDATE(START_DATE,F37-1) -> 46419 | G38: =EDATE(START_DATE,G37-1) -> 46447 | H38: =EDATE(START_DATE,H37-1) -> 46478 | I38: =EDATE(START_DATE,I37-1) -> 46508 | J38: =EDATE(START_DATE,J37-1) -> 46539 | K38: =EDATE(START_DATE,K37-1) -> 46569 | L38: =EDATE(START_DATE,L37-1) -> 46600 | ... KF38: =EDATE(START_DATE,KF37-1) -> 55123
B39: Construction month flag | C39: flag | D39: =SUM(E39:KF39) -> 30 | E39: =IF(E37<=CONSTR_EFF,1,0) -> 1 | F39: =IF(F37<=CONSTR_EFF,1,0) -> 1 | G39: =IF(G37<=CONSTR_EFF,1,0) -> 1 | H39: =IF(H37<=CONSTR_EFF,1,0) -> 1 | I39: =IF(I37<=CONSTR_EFF,1,0) -> 1 | J39: =IF(J37<=CONSTR_EFF,1,0) -> 1 | K39: =IF(K37<=CONSTR_EFF,1,0) -> 1 | L39: =IF(L37<=CONSTR_EFF,1,0) -> 1 | ... KF39: =IF(KF37<=CONSTR_EFF,1,0) -> 0
B40: Months after completion k | C40: no. | E40: =E37-CONSTR_EFF -> -29 | F40: =F37-CONSTR_EFF -> -28 | G40: =G37-CONSTR_EFF -> -27 | H40: =H37-CONSTR_EFF -> -26 | I40: =I37-CONSTR_EFF -> -25 | J40: =J37-CONSTR_EFF -> -24 | K40: =K37-CONSTR_EFF -> -23 | L40: =L37-CONSTR_EFF -> -22 | ... KF40: =KF37-CONSTR_EFF -> 258
B41: Operating year (within O1–O10) | C41: no. | E41: =IF(AND(E40>=1,E40<=12*OPS_YEARS),ROUNDUP(E40/12,0),0) -> 0 | F41: =IF(AND(F40>=1,F40<=12*OPS_YEARS),ROUNDUP(F40/12,0),0) -> 0 | G41: =IF(AND(G40>=1,G40<=12*OPS_YEARS),ROUNDUP(G40/12,0),0) -> 0 | H41: =IF(AND(H40>=1,H40<=12*OPS_YEARS),ROUNDUP(H40/12,0),0) -> 0 | I41: =IF(AND(I40>=1,I40<=12*OPS_YEARS),ROUNDUP(I40/12,0),0) -> 0 | J41: =IF(AND(J40>=1,J40<=12*OPS_YEARS),ROUNDUP(J40/12,0),0) -> 0 | K41: =IF(AND(K40>=1,K40<=12*OPS_YEARS),ROUNDUP(K40/12,0),0) -> 0 | L41: =IF(AND(L40>=1,L40<=12*OPS_YEARS),ROUNDUP(L40/12,0),0) -> 0 | ... KF41: =IF(AND(KF40>=1,KF40<=12*OPS_YEARS),ROUNDUP(KF40/12,0),0) -> 0
B42: Loan year after completion | C42: no. | E42: =IF(E40>=1,ROUNDUP(E40/12,0),0) -> 0 | F42: =IF(F40>=1,ROUNDUP(F40/12,0),0) -> 0 | G42: =IF(G40>=1,ROUNDUP(G40/12,0),0) -> 0 | H42: =IF(H40>=1,ROUNDUP(H40/12,0),0) -> 0 | I42: =IF(I40>=1,ROUNDUP(I40/12,0),0) -> 0 | J42: =IF(J40>=1,ROUNDUP(J40/12,0),0) -> 0 | K42: =IF(K40>=1,ROUNDUP(K40/12,0),0) -> 0 | L42: =IF(L40>=1,ROUNDUP(L40/12,0),0) -> 0 | ... KF42: =IF(KF40>=1,ROUNDUP(KF40/12,0),0) -> 22
B43: Annual period index (1–14, 0 = beyond horizon) | C43: no. | E43: =IF(E37<=CONSTR_EFF,ROUNDUP(E37/12,0),IF(E41>0,4+E41,0)) -> 1 | F43: =IF(F37<=CONSTR_EFF,ROUNDUP(F37/12,0),IF(F41>0,4+F41,0)) -> 1 | G43: =IF(G37<=CONSTR_EFF,ROUNDUP(G37/12,0),IF(G41>0,4+G41,0)) -> 1 | H43: =IF(H37<=CONSTR_EFF,ROUNDUP(H37/12,0),IF(H41>0,4+H41,0)) -> 1 | I43: =IF(I37<=CONSTR_EFF,ROUNDUP(I37/12,0),IF(I41>0,4+I41,0)) -> 1 | J43: =IF(J37<=CONSTR_EFF,ROUNDUP(J37/12,0),IF(J41>0,4+J41,0)) -> 1 | K43: =IF(K37<=CONSTR_EFF,ROUNDUP(K37/12,0),IF(K41>0,4+K41,0)) -> 1 | L43: =IF(L37<=CONSTR_EFF,ROUNDUP(L37/12,0),IF(L41>0,4+L41,0)) -> 1 | ... KF43: =IF(KF37<=CONSTR_EFF,ROUNDUP(KF37/12,0),IF(KF41>0,4+KF41,0)) -> 0

Sheet 21_Area
B1: 21 · Area programme | T1: =HYPERLINK("#'00_Start'!A1","◂ Start") -> ◂ Start
B2: የቦታና የወለል ስፋት ፕሮግራም
B3: =PROJ_NAME&" | Scenario: "&SCEN_NAME&" | Mode: "&MODE_NAME -> SAMPLE B — B+G+8 mixed-use building, Addis Ababa | Scenario: Base | Mode: 3 Mixed
B10: Floors (from Inputs block 3) | C10: ፎቆች
B11: Floor | E11: Basement 2 | F11: Basement 1 | G11: Ground floor | H11: Floor 1 | I11: Floor 2 | J11: Floor 3 | K11: Floor 4 | L11: Floor 5 | M11: Floor 6 | N11: Floor 7 | O11: Floor 8 | P11: Floor 9 | Q11: Floor 10 | R11: Floor 11 | S11: Floor 12 | T11: Floor 13
B12: Gross floor area | C12: m² | D12: =SUM(E12:T12) -> 6400 | E12: =FL_A1 -> 0 | F12: =FL_A2 -> 900 | G12: =FL_A3 -> 650 | H12: =FL_A4 -> 650 | I12: =FL_A5 -> 600 | J12: =FL_A6 -> 600 | K12: =FL_A7 -> 600 | L12: =FL_A8 -> 600 | M12: =FL_A9 -> 600 | N12: =FL_A10 -> 600 | O12: =FL_A11 -> 600 | P12: =FL_A12 -> 0 | Q12: =FL_A13 -> 0 | R12: =FL_A14 -> 0 | S12: =FL_A15 -> 0 | T12: =FL_A16 -> 0
B13: Use | E13: =FL_U1 -> Parking | F13: =FL_U2 -> Parking | G13: =FL_U3 -> Retail | H13: =FL_U4 -> Retail | I13: =FL_U5 -> Residential | J13: =FL_U6 -> Residential | K13: =FL_U7 -> Residential | L13: =FL_U8 -> Residential | M13: =FL_U9 -> Residential | N13: =FL_U10 -> Residential | O13: =FL_U11 -> Residential | P13: =FL_U12 -> Residential | Q13: =FL_U13 -> Residential | R13: =FL_U14 -> Residential | S13: =FL_U15 -> Residential | T13: =FL_U16 -> Residential
B14: Basement flag | C14: flag | E14: 1 | F14: 1 | G14: 0 | H14: 0 | I14: 0 | J14: 0 | K14: 0 | L14: 0 | M14: 0 | N14: 0 | O14: 0 | P14: 0 | Q14: 0 | R14: 0 | S14: 0 | T14: 0
B15: Floor built flag | C15: flag | D15: =SUM(E15:T15) -> 10 | E15: =IF(E12>0,1,0) -> 0 | F15: =IF(F12>0,1,0) -> 1 | G15: =IF(G12>0,1,0) -> 1 | H15: =IF(H12>0,1,0) -> 1 | I15: =IF(I12>0,1,0) -> 1 | J15: =IF(J12>0,1,0) -> 1 | K15: =IF(K12>0,1,0) -> 1 | L15: =IF(L12>0,1,0) -> 1 | ... T15: =IF(T12>0,1,0) -> 0
B17: Building summary | C17: የሕንፃ ማጠቃለያ
B18: Gross floor area (GFA) | C18: m² | D18: =SUM(E12:T12) -> 6400
B19: Basement gross area | C19: m² | D19: =SUMPRODUCT(E12:T12,E14:T14) -> 900
B20: Above-ground gross area | C20: m² | D20: =GFA-GFA_BASE -> 5500
B21: Above-ground floors built | C21: no. | D21: =SUM(G15:T15) -> 9
B22: Basement levels built | C22: no. | D22: =SUM(E15:F15) -> 1
B23: Building configuration | D23: =IF(N_BASE>0,"B"&N_BASE&"+","")&"G+"&MAX(0,N_ABOVE-1) -> B1+G+8
B24: Ground-floor footprint | C24: m² | D24: =G12 -> 650
B25: Actual FAR (above-ground GFA ÷ plot) | C25: x | D25: =IF(PLOT_AREA>0,GFA_ABOVE/PLOT_AREA,0) -> 5.5
B26: Building type matches floors entered (1 = yes) | C26: flag | D26: =IF(AND(IF(BLDG_TYPE=5,1,IF(N_ABOVE=BLDG_TYPE,1,0))=1,IF(BASEMENT_YN=1,N_BASE>0,N_BASE=0)),1,0) -> 1
B28: By use – areas and disposition (IAS 2 sold · IAS 40 let · IAS 16 owner-occupied) | C28: በአገልግሎት
B29: Use | E29: Residential | F29: Retail | G29: Office | H29: Parking | I29: Other
B30: Gross area | C30: m² | D30: =SUM(E30:I30) -> 6400 | E30: =SUMIF($E$13:$T$13,E29,$E$12:$T$12) -> 4200 | F30: =SUMIF($E$13:$T$13,F29,$E$12:$T$12) -> 1300 | G30: =SUMIF($E$13:$T$13,G29,$E$12:$T$12) -> 0 | H30: =SUMIF($E$13:$T$13,H29,$E$12:$T$12) -> 900 | I30: =SUMIF($E$13:$T$13,I29,$E$12:$T$12) -> 0
B31: Net-to-gross efficiency | C31: % | E31: =EFF_RES -> 0.8 | F31: =EFF_RET -> 0.85 | G31: =EFF_OFF -> 0.82 | H31: =EFF_PAR -> 0 | I31: =EFF_OTH -> 0
B32: Net saleable / lettable area | C32: m² | D32: =SUM(E32:I32) -> 4465 | E32: =E30*E31 -> 3360 | F32: =F30*F31 -> 1105 | G32: =G30*G31 -> 0 | H32: =H30*H31 -> 0 | I32: =I30*I31 -> 0
B33: Share sold (IAS 2) | C33: % | E33: =CHOOSE(PROJECT_MODE+1,0,1-OWNUSE_PCT,0,SOLD_RES) -> 1 | F33: =CHOOSE(PROJECT_MODE+1,0,1-OWNUSE_PCT,0,SOLD_RET) -> 0 | G33: =CHOOSE(PROJECT_MODE+1,0,1-OWNUSE_PCT,0,SOLD_OFF) -> 0 | H33: =CHOOSE(PROJECT_MODE+1,0,1-OWNUSE_PCT,0,SOLD_PAR) -> 0 | I33: =CHOOSE(PROJECT_MODE+1,0,1-OWNUSE_PCT,0,SOLD_OTH) -> 0
B34: Share owner-occupied (IAS 16) | C34: % | E34: =CHOOSE(PROJECT_MODE+1,1-HOME_RENT_SH,OWNUSE_PCT,OWNUSE_PCT,OWNUSE_PCT*(1-E33)) -> 0 | F34: =CHOOSE(PROJECT_MODE+1,1-HOME_RENT_SH,OWNUSE_PCT,OWNUSE_PCT,OWNUSE_PCT*(1-F33)) -> 0 | G34: =CHOOSE(PROJECT_MODE+1,1-HOME_RENT_SH,OWNUSE_PCT,OWNUSE_PCT,OWNUSE_PCT*(1-G33)) -> 0 | H34: =CHOOSE(PROJECT_MODE+1,1-HOME_RENT_SH,OWNUSE_PCT,OWNUSE_PCT,OWNUSE_PCT*(1-H33)) -> 0 | I34: =CHOOSE(PROJECT_MODE+1,1-HOME_RENT_SH,OWNUSE_PCT,OWNUSE_PCT,OWNUSE_PCT*(1-I33)) -> 0
B35: Share let (IAS 40) | C35: % | E35: =1-E33-E34 -> 0 | F35: =1-F33-F34 -> 1 | G35: =1-G33-G34 -> 1 | H35: =1-H33-H34 -> 1 | I35: =1-I33-I34 -> 1
B36: Saleable area | C36: m² | D36: =SUM(E36:I36) -> 3360 | E36: =E32*E33 -> 3360 | F36: =F32*F33 -> 0 | G36: =G32*G33 -> 0 | H36: =H32*H33 -> 0 | I36: =I32*I33 -> 0
B37: Lettable area | C37: m² | D37: =SUM(E37:I37) -> 1105 | E37: =E32*E35 -> 0 | F37: =F32*F35 -> 1105 | G37: =G32*G35 -> 0 | H37: =H32*H35 -> 0 | I37: =I32*I35 -> 0
B38: Owner-occupied area | C38: m² | D38: =SUM(E38:I38) -> 0 | E38: =E32*E34 -> 0 | F38: =F32*F34 -> 0 | G38: =G32*G34 -> 0 | H38: =H32*H34 -> 0 | I38: =I32*I34 -> 0
B39: Sale price (today) | C39: ETB/m² | E39: =PRICE_RES -> 125000 | F39: =PRICE_RET -> 180000 | G39: =PRICE_OFF -> 110000 | H39: =PRICE_PAR -> 0 | I39: =PRICE_OTH -> 0
B40: Rent (today) | C40: ETB/m²/mo | E40: =RENT_RES -> 650 | F40: =RENT_RET -> 2000 | G40: =RENT_OFF -> 900 | H40: =RENT_PAR -> 0 | I40: =RENT_OTH -> 0
B41: Sales value (today's prices) | C41: ETB | D41: =SUM(E41:I41) -> 420000000 | E41: =E36*E39 -> 420000000 | F41: =F36*F39 -> 0 | G41: =G36*G39 -> 0 | H41: =H36*H39 -> 0 | I41: =I36*I39 -> 0
B42: Potential rent p.a. (today's prices) | C42: ETB | D42: =SUM(E42:I42) -> 26520000 | E42: =E37*E40*12 -> 0 | F42: =F37*F40*12 -> 26520000 | G42: =G37*G40*12 -> 0 | H42: =H37*H40*12 -> 0 | I42: =I37*I40*12 -> 0
B44: Area totals and allocation shares | C44: ጠቅላላ ስፋትና የወጪ ድልድል
B45: Net area (all uses) | C45: m² | D45: =$D$32 -> 4465
B46: Mode 0: share of house rented out | C46: % | D46: =IF(AND(RENT_HOME_F=1,NET_AREA>0),MIN(1,RENT_HOME_AREA/NET_AREA),0) -> 0
B47: Saleable area | C47: m² | D47: =$D$36 -> 3360
B48: Lettable area | C48: m² | D48: =$D$37 -> 1105
B49: Owner-occupied area | C49: m² | D49: =$D$38 -> 0
...

Sheet 22_Capex
B1: 22 · Capex – elemental BOQ, soft costs, land | L1: =HYPERLINK("#'00_Start'!A1","◂ Start") -> ◂ Start
B2: የካፒታል ወጪ – የግንባታ ዝርዝር
